<?xml version="1.0" encoding="utf-8"?>
<!-- This URDF was automatically created by SolidWorks to URDF Exporter! Originally created by Stephen Brawner (brawner@gmail.com) 
     Commit Version: 1.6.0-4-g7f85cfe  Build Version: 1.6.7995.38578
     For more information, please see http://wiki.ros.org/sw_urdf_exporter -->
<robot
  name="gantry2">
  <link
    name="base_link">
    <inertial>
      <origin
        xyz="-0.121865978640306 -0.273897828438086 0.0246456837369903"
        rpy="0 0 0" />
      <mass
        value="0.999102566782323" />
      <inertia
        ixx="0.000487090542499096"
        ixy="-1.69716831441622E-05"
        ixz="6.79121092917164E-07"
        iyy="0.0112944978686566"
        iyz="-1.93331648583656E-08"
        izz="0.0114768570045446" />
    </inertial>
    <visual>
      <origin
        xyz="0 0 0"
        rpy="0 0 0" />
      <geometry>
        <mesh
          filename="package://gantry2/meshes/base_link.STL" />
      </geometry>
      <material
        name="">
        <color
          rgba="0.792156862745098 0.819607843137255 0.933333333333333 1" />
      </material>
    </visual>
    <collision>
      <origin
        xyz="0 0 0"
        rpy="0 0 0" />
      <geometry>
        <mesh
          filename="package://gantry2/meshes/base_link.STL" />
      </geometry>
    </collision>
  </link>
  <link
    name="X_gantry">
    <inertial>
      <origin
        xyz="-0.330445600953596 0.41243845615363 0.719872312327481"
        rpy="0 0 0" />
      <mass
        value="2.71844086885816" />
      <inertia
        ixx="0.0276076361373676"
        ixy="-7.81803234908446E-05"
        ixz="-0.0089490452395312"
        iyy="0.0300491640122015"
        iyz="3.21854109229722E-05"
        izz="0.00955363785666674" />
    </inertial>
    <visual>
      <origin
        xyz="0 0 0"
        rpy="0 0 0" />
      <geometry>
        <mesh
          filename="package://gantry2/meshes/X_gantry.STL" />
      </geometry>
      <material
        name="">
        <color
          rgba="0.792156862745098 0.819607843137255 0.933333333333333 1" />
      </material>
    </visual>
    <collision>
      <origin
        xyz="0 0 0"
        rpy="0 0 0" />
      <geometry>
        <mesh
          filename="package://gantry2/meshes/X_gantry.STL" />
      </geometry>
    </collision>
  </link>
  <joint
    name="X_gantry"
    type="prismatic">
    <origin
      xyz="0.384039296465491 0.296155016969451 -0.511878593824796"
      rpy="1.5707963267949 0 -0.388845869999989" />
    <parent
      link="base_link" />
    <child
      link="X_gantry" />
    <axis
      xyz="0.924707224857576 0 -0.380679062066986" />
    <limit
      lower="0"
      upper="0"
      effort="0"
      velocity="0" />
  </joint>
  <link
    name="Y_gantry">
    <inertial>
      <origin
        xyz="-0.406226038392111 0.330664773639603 0.775987322827041"
        rpy="0 0 0" />
      <mass
        value="1.32530018051395" />
      <inertia
        ixx="0.0068727595486413"
        ixy="-6.67237256068689E-07"
        ixz="-0.000824318311271524"
        iyy="0.00261475168890882"
        iyz="2.0555067490779E-07"
        izz="0.00521023975730692" />
    </inertial>
    <visual>
      <origin
        xyz="0 0 0"
        rpy="0 0 0" />
      <geometry>
        <mesh
          filename="package://gantry2/meshes/Y_gantry.STL" />
      </geometry>
      <material
        name="">
        <color
          rgba="0.792156862745098 0.819607843137255 0.933333333333333 1" />
      </material>
    </visual>
    <collision>
      <origin
        xyz="0 0 0"
        rpy="0 0 0" />
      <geometry>
        <mesh
          filename="package://gantry2/meshes/Y_gantry.STL" />
      </geometry>
    </collision>
  </link>
  <joint
    name="Y_gantry"
    type="prismatic">
    <origin
      xyz="-0.016803 0 -0.040816"
      rpy="0 0 0" />
    <parent
      link="X_gantry" />
    <child
      link="Y_gantry" />
    <axis
      xyz="0.38068 0 0.92471" />
    <limit
      lower="0"
      upper="0"
      effort="0"
      velocity="0" />
  </joint>
  <link
    name="Z_gantry">
    <inertial>
      <origin
        xyz="-0.456176963862741 0.360694369203997 0.796550543642087"
        rpy="0 0 0" />
      <mass
        value="0.403068685222285" />
      <inertia
        ixx="0.001069651416775"
        ixy="-2.56265949484876E-07"
        ixz="-0.000122132318441185"
        iyy="0.000362088816464686"
        iyz="6.50889057713317E-08"
        izz="0.000823258357325589" />
    </inertial>
    <visual>
      <origin
        xyz="0 0 0"
        rpy="0 0 0" />
      <geometry>
        <mesh
          filename="package://gantry2/meshes/Z_gantry.STL" />
      </geometry>
      <material
        name="">
        <color
          rgba="0.792156862745098 0.819607843137255 0.933333333333333 1" />
      </material>
    </visual>
    <collision>
      <origin
        xyz="0 0 0"
        rpy="0 0 0" />
      <geometry>
        <mesh
          filename="package://gantry2/meshes/Z_gantry.STL" />
      </geometry>
    </collision>
  </link>
  <joint
    name="Z_gantry"
    type="prismatic">
    <origin
      xyz="0 -0.057303 0"
      rpy="0 0 0" />
    <parent
      link="Y_gantry" />
    <child
      link="Z_gantry" />
    <axis
      xyz="0 1 0" />
    <limit
      lower="0"
      upper="0"
      effort="0"
      velocity="0" />
  </joint>
  <link
    name="R_arm">
    <inertial>
      <origin
        xyz="0.000172992865795168 9.99205362598177E-05 0.158656494242956"
        rpy="0 0 0" />
      <mass
        value="0.40832410475707" />
      <inertia
        ixx="0.00270494526203626"
        ixy="-1.15577645652849E-18"
        ixz="5.79230425117883E-09"
        iyy="0.00273630527789283"
        iyz="4.93932362761744E-09"
        izz="0.000324233567972814" />
    </inertial>
    <visual>
      <origin
        xyz="0 0 0"
        rpy="0 0 0" />
      <geometry>
        <mesh
          filename="package://gantry2/meshes/R_arm.STL" />
      </geometry>
      <material
        name="">
        <color
          rgba="0.792156862745098 0.819607843137255 0.933333333333333 1" />
      </material>
    </visual>
    <collision>
      <origin
        xyz="0 0 0"
        rpy="0 0 0" />
      <geometry>
        <mesh
          filename="package://gantry2/meshes/R_arm.STL" />
      </geometry>
    </collision>
  </link>
  <joint
    name="R_arm"
    type="continuous">
    <origin
      xyz="-0.471819627899255 0.356052852730416 0.803144304946078"
      rpy="-0.00564683816729087 -1.18025922404267 0.00610662824055455" />
    <parent
      link="Z_gantry" />
    <child
      link="R_arm" />
    <axis
      xyz="0 0 1" />
  </joint>
  <link
    name="TMS_1">
    <inertial>
      <origin
        xyz="0.000114831415910233 1.85573778566095E-13 0.000278936906747407"
        rpy="0 0 0" />
      <mass
        value="0.0116350451938088" />
      <inertia
        ixx="4.3766659154405E-06"
        ixy="9.70035806131879E-08"
        ixz="-1.54880682052681E-06"
        iyy="4.79724370288521E-06"
        iyz="-3.99339716323589E-08"
        izz="1.25206583486368E-06" />
    </inertial>
    <visual>
      <origin
        xyz="0 0 0"
        rpy="0 0 0" />
      <geometry>
        <mesh
          filename="package://gantry2/meshes/TMS_1.STL" />
      </geometry>
      <material
        name="">
        <color
          rgba="0.792156862745098 0.819607843137255 0.933333333333333 1" />
      </material>
    </visual>
    <collision>
      <origin
        xyz="0 0 0"
        rpy="0 0 0" />
      <geometry>
        <mesh
          filename="package://gantry2/meshes/TMS_1.STL" />
      </geometry>
    </collision>
  </link>
  <joint
    name="TMS_1"
    type="continuous">
    <origin
      xyz="0 0.000250000000013711 0.347848885049497"
      rpy="-0.875623012470802 0.999554617960551 -0.789671704770428" />
    <parent
      link="R_arm" />
    <child
      link="TMS_1" />
    <axis
      xyz="0.380679062067115 0 0.924707224857523" />
  </joint>
  <link
    name="TMS_2">
    <inertial>
      <origin
        xyz="-0.0275370440622424 -0.0116708971830498 0.011361808424475"
        rpy="0 0 0" />
      <mass
        value="0.0428411642677234" />
      <inertia
        ixx="9.69581929377774E-06"
        ixy="-8.55825648543455E-07"
        ixz="8.05759888760884E-07"
        iyy="1.12788798612566E-05"
        iyz="3.52375889302879E-07"
        izz="1.13213907041868E-05" />
    </inertial>
    <visual>
      <origin
        xyz="0 0 0"
        rpy="0 0 0" />
      <geometry>
        <mesh
          filename="package://gantry2/meshes/TMS_2.STL" />
      </geometry>
      <material
        name="">
        <color
          rgba="0.792156862745098 0.819607843137255 0.933333333333333 1" />
      </material>
    </visual>
    <collision>
      <origin
        xyz="0 0 0"
        rpy="0 0 0" />
      <geometry>
        <mesh
          filename="package://gantry2/meshes/TMS_2.STL" />
      </geometry>
    </collision>
  </link>
  <joint
    name="TMS_2"
    type="continuous">
    <origin
      xyz="0 0 0"
      rpy="1.32449423379942 0.715487506794452 -0.0697245512363634" />
    <parent
      link="TMS_1" />
    <child
      link="TMS_2" />
    <axis
      xyz="0.857281644428845 0.374852653552844 -0.352921620547349" />
  </joint>
</robot>