<?xml version="1.0" encoding="utf-8"?>
<!-- This URDF was automatically created by SolidWorks to URDF Exporter! Originally created by Stephen Brawner (brawner@gmail.com) 
     Commit Version: 1.6.0-4-g7f85cfe  Build Version: 1.6.7995.38578
     For more information, please see http://wiki.ros.org/sw_urdf_exporter -->
<robot
  name="gantry">
  <link
    name="base_link">
    <inertial>
      <origin
        xyz="-0.121865978640207 0.0246456837370067 0.27389782843817"
        rpy="0 0 0" />
      <mass
        value="0.999102566779981" />
      <inertia
        ixx="0.000487090542498852"
        ixy="6.79121092916842E-07"
        ixz="1.69716831439906E-05"
        iyy="0.0114768570045443"
        iyz="1.93331648577645E-08"
        izz="0.0112944978686564" />
    </inertial>
    <visual>
      <origin
        xyz="0 0 0"
        rpy="0 0 0" />
      <geometry>
        <mesh
          filename="package://gantry/meshes/base_link.STL" />
      </geometry>
      <material
        name="">
        <color
          rgba="0.792156862745098 0.819607843137255 0.933333333333333 1" />
      </material>
    </visual>
    <collision>
      <origin
        xyz="0 0 0"
        rpy="0 0 0" />
      <geometry>
        <mesh
          filename="package://gantry/meshes/base_link.STL" />
      </geometry>
    </collision>
  </link>
  <link
    name="X_gantry">
    <inertial>
      <origin
        xyz="-0.330445600953593 0.412438456153616 0.719872312327478"
        rpy="0 0 0" />
      <mass
        value="2.71844086885816" />
      <inertia
        ixx="0.0276076361373676"
        ixy="-7.81803234908446E-05"
        ixz="-0.00894904523953119"
        iyy="0.0300491640122015"
        iyz="3.21854109229722E-05"
        izz="0.00955363785666674" />
    </inertial>
    <visual>
      <origin
        xyz="0 0 0"
        rpy="0 0 0" />
      <geometry>
        <mesh
          filename="package://gantry/meshes/X_gantry.STL" />
      </geometry>
      <material
        name="">
        <color
          rgba="0.792156862745098 0.819607843137255 0.933333333333333 1" />
      </material>
    </visual>
    <collision>
      <origin
        xyz="0 0 0"
        rpy="0 0 0" />
      <geometry>
        <mesh
          filename="package://gantry/meshes/X_gantry.STL" />
      </geometry>
    </collision>
  </link>
  <joint
    name="X_gantry"
    type="fixed">
    <origin
      xyz="0.384039296465491 0.296155016969451 -0.511878593824796"
      rpy="1.5707963267949 0 -0.388845869999989" />
    <parent
      link="base_link" />
    <child
      link="X_gantry" />
    <axis
      xyz="0 0 0" />
  </joint>
  <link
    name="Y_gantry">
    <inertial>
      <origin
        xyz="-0.406226038392143 0.330664773639583 0.775987322826961"
        rpy="0 0 0" />
      <mass
        value="1.32530018051395" />
      <inertia
        ixx="0.0068727595486413"
        ixy="-6.67237256068692E-07"
        ixz="-0.000824318311271524"
        iyy="0.00261475168890882"
        iyz="2.05550674907776E-07"
        izz="0.00521023975730692" />
    </inertial>
    <visual>
      <origin
        xyz="0 0 0"
        rpy="0 0 0" />
      <geometry>
        <mesh
          filename="package://gantry/meshes/Y_gantry.STL" />
      </geometry>
      <material
        name="">
        <color
          rgba="0.792156862745098 0.819607843137255 0.933333333333333 1" />
      </material>
    </visual>
    <collision>
      <origin
        xyz="0 0 0"
        rpy="0 0 0" />
      <geometry>
        <mesh
          filename="package://gantry/meshes/Y_gantry.STL" />
      </geometry>
    </collision>
  </link>
  <joint
    name="Y_gantry"
    type="fixed">
    <origin
      xyz="-0.0168029342943233 0 -0.040815995123041"
      rpy="0 0 0" />
    <parent
      link="X_gantry" />
    <child
      link="Y_gantry" />
    <axis
      xyz="0 0 0" />
  </joint>
  <link
    name="Z_gantry">
    <inertial>
      <origin
        xyz="-0.45617696386277 0.360694369203785 0.796550543641971"
        rpy="0 0 0" />
      <mass
        value="0.403068685222285" />
      <inertia
        ixx="0.001069651416775"
        ixy="-2.56265949484883E-07"
        ixz="-0.000122132318441185"
        iyy="0.000362088816464686"
        iyz="6.50889057713201E-08"
        izz="0.000823258357325589" />
    </inertial>
    <visual>
      <origin
        xyz="0 0 0"
        rpy="0 0 0" />
      <geometry>
        <mesh
          filename="package://gantry/meshes/Z_gantry.STL" />
      </geometry>
      <material
        name="">
        <color
          rgba="0.792156862745098 0.819607843137255 0.933333333333333 1" />
      </material>
    </visual>
    <collision>
      <origin
        xyz="0 0 0"
        rpy="0 0 0" />
      <geometry>
        <mesh
          filename="package://gantry/meshes/Z_gantry.STL" />
      </geometry>
    </collision>
  </link>
  <joint
    name="Z_gantry"
    type="fixed">
    <origin
      xyz="0 -0.0573029839450929 0"
      rpy="0 0 0" />
    <parent
      link="Y_gantry" />
    <child
      link="Z_gantry" />
    <axis
      xyz="0 0 0" />
  </joint>
  <link
    name="Arm">
    <inertial>
      <origin
        xyz="0.000172992865675708 9.99205360479039E-05 0.158656494242938"
        rpy="0 0 0" />
      <mass
        value="0.40832410475707" />
      <inertia
        ixx="0.00270494526203626"
        ixy="-1.15619997300212E-18"
        ixz="5.79230425117364E-09"
        iyy="0.00273630527789283"
        iyz="4.93932362760822E-09"
        izz="0.000324233567972814" />
    </inertial>
    <visual>
      <origin
        xyz="0 0 0"
        rpy="0 0 0" />
      <geometry>
        <mesh
          filename="package://gantry/meshes/Arm.STL" />
      </geometry>
      <material
        name="">
        <color
          rgba="0.792156862745098 0.819607843137255 0.933333333333333 1" />
      </material>
    </visual>
    <collision>
      <origin
        xyz="0 0 0"
        rpy="0 0 0" />
      <geometry>
        <mesh
          filename="package://gantry/meshes/Arm.STL" />
      </geometry>
    </collision>
  </link>
  <joint
    name="Arm"
    type="continuous">
    <origin
      xyz="-0.471819627899255 0.356052852730415 0.803144304946078"
      rpy="-0.00564683816729087 -1.18025922404267 0.00610662824055455" />
    <parent
      link="Z_gantry" />
    <child
      link="Arm" />
    <axis
      xyz="0 0 1" />
  </joint>
  <link
    name="gear_1">
    <inertial>
      <origin
        xyz="-0.0110822796622391 1.78874089429293E-07 -0.0269199712581503"
        rpy="0 0 0" />
      <mass
        value="0.0268121295267774" />
      <inertia
        ixx="4.86794511120438E-06"
        ixy="9.15046180284066E-12"
        ixz="5.39303693297034E-07"
        iyy="4.64593436015291E-06"
        iyz="-3.6826761594354E-11"
        izz="5.95595049268311E-06" />
    </inertial>
    <visual>
      <origin
        xyz="0 0 0"
        rpy="0 0 0" />
      <geometry>
        <mesh
          filename="package://gantry/meshes/gear_1.STL" />
      </geometry>
      <material
        name="">
        <color
          rgba="0.792156862745098 0.819607843137255 0.933333333333333 1" />
      </material>
    </visual>
    <collision>
      <origin
        xyz="0 0 0"
        rpy="0 0 0" />
      <geometry>
        <mesh
          filename="package://gantry/meshes/gear_1.STL" />
      </geometry>
    </collision>
  </link>
  <joint
    name="gear_1"
    type="continuous">
    <origin
      xyz="-0.00210171250473482 0.000250000000013628 0.347848885049495"
      rpy="2.08883588549031 -0.877218810892848 0.932946344800027" />
    <parent
      link="Arm" />
    <child
      link="gear_1" />
    <axis
      xyz="0.380679062067145 0 0.92470722485751" />
  </joint>
  <link
    name="gear_2">
    <inertial>
      <origin
        xyz="0.0110705572381198 1.77162194942015E-07 0.0268914407863081"
        rpy="0 0 0" />
      <mass
        value="0.0268121325316845" />
      <inertia
        ixx="4.8679440838271E-06"
        ixy="-7.87439687765173E-12"
        ixz="5.39308264291753E-07"
        iyy="4.64594059206303E-06"
        iyz="3.59578856514638E-11"
        izz="5.95594839816363E-06" />
    </inertial>
    <visual>
      <origin
        xyz="0 0 0"
        rpy="0 0 0" />
      <geometry>
        <mesh
          filename="package://gantry/meshes/gear_2.STL" />
      </geometry>
      <material
        name="">
        <color
          rgba="0.792156862745098 0.819607843137255 0.933333333333333 1" />
      </material>
    </visual>
    <collision>
      <origin
        xyz="0 0 0"
        rpy="0 0 0" />
      <geometry>
        <mesh
          filename="package://gantry/meshes/gear_2.STL" />
      </geometry>
    </collision>
  </link>
  <joint
    name="gear_2"
    type="continuous">
    <origin
      xyz="0.00263255624415029 0.000250000000042966 0.347848885049495"
      rpy="-3.06605400025714 -1.1792594925658 -0.0698414933414174" />
    <parent
      link="Arm" />
    <child
      link="gear_2" />
    <axis
      xyz="0.380679062067064 0 0.924707224857544" />
  </joint>
  <link
    name="TMS_gear">
    <inertial>
      <origin
        xyz="-0.678599530574604 0.241654276661634 0.938612017527155"
        rpy="0 0 0" />
      <mass
        value="0.0428411642677233" />
      <inertia
        ixx="9.69581929377774E-06"
        ixy="-8.55825648543421E-07"
        ixz="8.05759888760873E-07"
        iyy="1.12788798612566E-05"
        iyz="3.52375889302861E-07"
        izz="1.13213907041867E-05" />
    </inertial>
    <visual>
      <origin
        xyz="0 0 0"
        rpy="0 0 0" />
      <geometry>
        <mesh
          filename="package://gantry/meshes/TMS_gear.STL" />
      </geometry>
      <material
        name="">
        <color
          rgba="0.792156862745098 0.819607843137255 0.933333333333333 1" />
      </material>
    </visual>
    <collision>
      <origin
        xyz="0 0 0"
        rpy="0 0 0" />
      <geometry>
        <mesh
          filename="package://gantry/meshes/TMS_gear.STL" />
      </geometry>
    </collision>
  </link>
  <joint
    name="TMS_gear"
    type="fixed">
    <origin
      xyz="-1.00907945081611 -0.508959801789388 -0.271857893788026"
      rpy="1.54029511978886 -0.018453554251524 2.65833929924169" />
    <parent
      link="gear_2" />
    <child
      link="TMS_gear" />
    <axis
      xyz="0 0 0" />
  </joint>
</robot>