<?xml version="1.0" encoding="utf-8"?>
<!-- This URDF was automatically created by SolidWorks to URDF Exporter! Originally created by Stephen Brawner (brawner@gmail.com) 
     Commit Version: 1.6.0-4-g7f85cfe  Build Version: 1.6.7995.38578
     For more information, please see http://wiki.ros.org/sw_urdf_exporter -->
<robot
  name="gantry">
  <link
    name="base_link">
    <inertial>
      <origin
        xyz="0.27339774606297 0.0196335701822426 -0.264075024281507"
        rpy="0 0 0" />
      <mass
        value="0.999102566760147" />
      <inertia
        ixx="0.000487064031842795"
        ixy="6.79087549106729E-07"
        ixz="1.23528453698545E-06"
        iyy="0.0114768570045405"
        iyz="-2.04757964896686E-08"
        izz="0.0112945243793064" />
    </inertial>
    <visual>
      <origin
        xyz="0 0 0"
        rpy="0 0 0" />
      <geometry>
        <mesh
          filename="package://gantry/meshes/base_link.STL" />
      </geometry>
      <material
        name="">
        <color
          rgba="0.792156862745098 0.819607843137255 0.933333333333333 1" />
      </material>
    </visual>
    <collision>
      <origin
        xyz="0 0 0"
        rpy="0 0 0" />
      <geometry>
        <mesh
          filename="package://gantry/meshes/base_link.STL" />
      </geometry>
    </collision>
  </link>
  <link
    name="X_Gantry_Link">
    <inertial>
      <origin
        xyz="-0.250897370416497 0.121219391821721 -0.118974126778729"
        rpy="0 0 0" />
      <mass
        value="2.7184408688585" />
      <inertia
        ixx="0.00586953459875889"
        ixy="-2.79508273559891E-10"
        ixz="-7.22728451990247E-09"
        iyy="0.0300491640122006"
        iyz="8.45462220164004E-05"
        izz="0.0312917393952745" />
    </inertial>
    <visual>
      <origin
        xyz="0 0 0"
        rpy="0 0 0" />
      <geometry>
        <mesh
          filename="package://gantry/meshes/X_Gantry_Link.STL" />
      </geometry>
      <material
        name="">
        <color
          rgba="0.792156862745098 0.819607843137255 0.933333333333333 1" />
      </material>
    </visual>
    <collision>
      <origin
        xyz="0 0 0"
        rpy="0 0 0" />
      <geometry>
        <mesh
          filename="package://gantry/meshes/X_Gantry_Link.STL" />
      </geometry>
    </collision>
  </link>
  <joint
    name="x_Gantry"
    type="prismatic">
    <origin
      xyz="0.067498 0.0425 0.0225"
      rpy="1.5708 0 -1.5708" />
    <parent
      link="base_link" />
    <child
      link="X_Gantry_Link" />
    <axis
      xyz="-1 0 0" />
    <limit
      lower="0"
      upper="0.3"
      effort="0"
      velocity="0" />
  </joint>
  <link
    name="Y_Gantry_Link">
    <inertial>
      <origin
        xyz="-0.100144651239357 -0.259006925809135 -0.0449081543375472"
        rpy="0 0 0" />
      <mass
        value="1.32530018007878" />
      <inertia
        ixx="0.00487081879798323"
        ixy="6.39112939867914E-08"
        ixz="-1.68886769690077E-07"
        iyy="0.00261475168874749"
        iyz="6.95247980957683E-07"
        izz="0.00721218050776161" />
    </inertial>
    <visual>
      <origin
        xyz="0 0 0"
        rpy="0 0 0" />
      <geometry>
        <mesh
          filename="package://gantry/meshes/Y_Gantry_Link.STL" />
      </geometry>
      <material
        name="">
        <color
          rgba="0.792156862745098 0.819607843137255 0.933333333333333 1" />
      </material>
    </visual>
    <collision>
      <origin
        xyz="0 0 0"
        rpy="0 0 0" />
      <geometry>
        <mesh
          filename="package://gantry/meshes/Y_Gantry_Link.STL" />
      </geometry>
    </collision>
  </link>
  <joint
    name="Y_Gantry"
    type="prismatic">
    <origin
      xyz="-0.242 0.462 -0.1655"
      rpy="0 0 0" />
    <parent
      link="X_Gantry_Link" />
    <child
      link="Y_Gantry_Link" />
    <axis
      xyz="0 -1 0" />
    <limit
      lower="-0.16"
      upper="0"
      effort="0"
      velocity="0" />
  </joint>
  <link
    name="Z_Gantry_Link">
    <inertial>
      <origin
        xyz="-0.0536424640855818 -0.104673786375891 -0.0399261236240419"
        rpy="0 0 0" />
      <mass
        value="0.403068685283753" />
      <inertia
        ixx="0.000772979562738817"
        ixy="3.73636664017519E-08"
        ixz="1.36135519341239E-10"
        iyy="0.000362088816461052"
        iyz="2.61748959077445E-07"
        izz="0.00111993021135161" />
    </inertial>
    <visual>
      <origin
        xyz="0 0 0"
        rpy="0 0 0" />
      <geometry>
        <mesh
          filename="package://gantry/meshes/Z_Gantry_Link.STL" />
      </geometry>
      <material
        name="">
        <color
          rgba="0.792156862745098 0.819607843137255 0.933333333333333 1" />
      </material>
    </visual>
    <collision>
      <origin
        xyz="0 0 0"
        rpy="0 0 0" />
      <geometry>
        <mesh
          filename="package://gantry/meshes/Z_Gantry_Link.STL" />
      </geometry>
    </collision>
  </link>
  <joint
    name="Z_Gantry"
    type="prismatic">
    <origin
      xyz="-0.046503 -0.079468 -0.059"
      rpy="0 0 0" />
    <parent
      link="Y_Gantry_Link" />
    <child
      link="Z_Gantry_Link" />
    <axis
      xyz="0 0 1" />
    <limit
      lower="0"
      upper="0.13"
      effort="0"
      velocity="0" />
  </joint>
  <link
    name="R_Arm_Link">
    <inertial>
      <origin
        xyz="0.000109473507310887 0.0560505796731903 0.138052363008648"
        rpy="0 0 0" />
      <mass
        value="0.645326600445391" />
      <inertia
        ixx="0.00306981338547555"
        ixy="1.71181564064318E-09"
        ixz="6.17685909876206E-09"
        iyy="0.00302834442807902"
        iyz="-9.03830003373786E-05"
        izz="0.00084053047929264" />
    </inertial>
    <visual>
      <origin
        xyz="0 0 0"
        rpy="0 0 0" />
      <geometry>
        <mesh
          filename="package://gantry/meshes/R_Arm_Link.STL" />
      </geometry>
      <material
        name="">
        <color
          rgba="0.792156862745098 0.819607843137255 0.933333333333333 1" />
      </material>
    </visual>
    <collision>
      <origin
        xyz="0 0 0"
        rpy="0 0 0" />
      <geometry>
        <mesh
          filename="package://gantry/meshes/R_Arm_Link.STL" />
      </geometry>
    </collision>
  </link>
  <joint
    name="R_Arm"
    type="continuous">
    <origin
      xyz="-0.0535 -0.10003 -0.0569"
      rpy="3.1416 0 3.1416" />
    <parent
      link="Z_Gantry_Link" />
    <child
      link="R_Arm_Link" />
    <axis
      xyz="1 0 0" />
  </joint>
  <link
    name="TMS_1_Link">
    <inertial>
      <origin
        xyz="-4.56840156564109E-05 3.11972669919669E-14 -1.47493128821452E-13"
        rpy="0 0 0" />
      <mass
        value="0.0116350451938088" />
      <inertia
        ixx="6.14460426457637E-07"
        ixy="-1.18039108553904E-20"
        ixz="3.26581801098026E-20"
        iyy="4.75482817954653E-06"
        iyz="-1.38066730978537E-21"
        izz="5.05668684718519E-06" />
    </inertial>
    <visual>
      <origin
        xyz="0 0 0"
        rpy="0 0 0" />
      <geometry>
        <mesh
          filename="package://gantry/meshes/TMS_1_Link.STL" />
      </geometry>
      <material
        name="">
        <color
          rgba="0.792156862745098 0.819607843137255 0.933333333333333 1" />
      </material>
    </visual>
    <collision>
      <origin
        xyz="0 0 0"
        rpy="0 0 0" />
      <geometry>
        <mesh
          filename="package://gantry/meshes/TMS_1_Link.STL" />
      </geometry>
    </collision>
  </link>
  <joint
    name="TMS_1"
    type="continuous">
    <origin
      xyz="0.000347 0.07525 0.3706"
      rpy="1.5708 0 0" />
    <parent
      link="R_Arm_Link" />
    <child
      link="TMS_1_Link" />
    <axis
      xyz="0 1 0" />
  </joint>
  <link
    name="TMS_HEAD_Link">
    <inertial>
      <origin
        xyz="-6.06167638306232E-09 3.13335891677369E-08 0.0319916748172523"
        rpy="0 0 0" />
      <mass
        value="0.0428412061325881" />
      <inertia
        ixx="1.16531775928806E-05"
        ixy="1.27768234211926E-13"
        ixz="-4.42322128864715E-13"
        iyy="1.16530809035071E-05"
        iyz="1.54673066118602E-11"
        izz="8.98989779655822E-06" />
    </inertial>
    <visual>
      <origin
        xyz="0 0 0"
        rpy="0 0 0" />
      <geometry>
        <mesh
          filename="package://gantry/meshes/TMS_HEAD_Link.STL" />
      </geometry>
      <material
        name="">
        <color
          rgba="0.792156862745098 0.819607843137255 0.933333333333333 1" />
      </material>
    </visual>
    <collision>
      <origin
        xyz="0 0 0"
        rpy="0 0 0" />
      <geometry>
        <mesh
          filename="package://gantry/meshes/TMS_HEAD_Link.STL" />
      </geometry>
    </collision>
  </link>
  <joint
    name="TMS_HEAD"
    type="continuous">
    <origin
      xyz="0 0 0"
      rpy="0 0 3.1416" />
    <parent
      link="TMS_1_Link" />
    <child
      link="TMS_HEAD_Link" />
    <axis
      xyz="1 0 0" />
  </joint>
</robot>