<?xml version="1.0" encoding="utf-8" ?>
<!-- This URDF was automatically created by SolidWorks to URDF Exporter! Originally created by Stephen Brawner (brawner@gmail.com) 
     Commit Version: 1.6.0-4-g7f85cfe  Build Version: 1.6.7995.38578
     For more information, please see http://wiki.ros.org/sw_urdf_exporter -->
<robot name="gantry">
    <link name="world" />
    <joint name="base_joint" type="fixed">
        <parent link="world" />
        <child link="base_link" />
        <origin rpy="0 0 0" xyz="0.0 0.0 0.17" />
    </joint>
    <link name="base_link">
        <inertial>
            <origin xyz="0.273397746062969 0.0196335701823842 0.290424975718704" rpy="0 0 0" />
            <mass value="0.999102566758599" />
            <inertia ixx="0.000487064031842296" ixy="6.79087549974893E-07" ixz="1.23528453577318E-06" iyy="0.0114768570045371" iyz="-2.04757967514068E-08" izz="0.0112945243793031" />
        </inertial>
        <visual>
            <origin xyz="0 0 0" rpy="0 0 0" />
            <geometry>
                <mesh filename="package://gantry/meshes/base_link.STL" />
            </geometry>
            <material name="">
                <color rgba="0.792156862745098 0.819607843137255 0.933333333333333 1" />
            </material>
        </visual>
        <collision>
            <origin xyz="0 0 0" rpy="0 0 0" />
            <geometry>
                <mesh filename="package://gantry/meshes/base_link.STL" />
            </geometry>
        </collision>
    </link>
    <link name="X_gantry_link">
        <inertial>
            <origin xyz="-0.0698541814264949 0.412438460402414 0.612593275517403" rpy="0 0 0" />
            <mass value="2.7184408688585" />
            <inertia ixx="0.0276076361378352" ixy="-7.8180395929004E-05" ixz="-0.00894904523905823" iyy="0.0300491640122007" iyz="3.21852349643491E-05" izz="0.00955363785619821" />
        </inertial>
        <visual>
            <origin xyz="0 0 0" rpy="0 0 0" />
            <geometry>
                <mesh filename="package://gantry/meshes/X_gantry.STL" />
            </geometry>
            <material name="">
                <color rgba="0.792156862745098 0.819607843137255 0.933333333333333 1" />
            </material>
        </visual>
        <collision>
            <origin xyz="0 0 0" rpy="0 0 0" />
            <geometry>
                <mesh filename="package://gantry/meshes/X_gantry.STL" />
            </geometry>
        </collision>
    </link>
    <joint name="X_gantry" type="prismatic">
        <origin xyz="-0.10352 0.27877 0.55616" rpy="-1.5708 0 -2.7511" />
        <parent link="base_link" />
        <child link="X_gantry_link" />
        <axis xyz="0.92471 0 -0.38068" />
        <limit lower="-0.28" upper="0" effort="0" velocity="0" />
    </joint>
    <link name="Y_gantry_link">
        <inertial>
            <origin xyz="-0.572532898605919 0.330664778033361 0.372011453080152" rpy="0 0 0" />
            <mass value="1.32530018007877" />
            <inertia ixx="0.00687275954854803" ixy="-6.672305225229E-07" ixz="-0.000824318311314372" iyy="0.00261475168874748" iyz="2.05567113830463E-07" izz="0.00521023975719679" />
        </inertial>
        <visual>
            <origin xyz="0 0 0" rpy="0 0 0" />
            <geometry>
                <mesh filename="package://gantry/meshes/Y_gantry.STL" />
            </geometry>
            <material name="">
                <color rgba="0.792156862745098 0.819607843137255 0.933333333333333 1" />
            </material>
        </visual>
        <collision>
            <origin xyz="0 0 0" rpy="0 0 0" />
            <geometry>
                <mesh filename="package://gantry/meshes/Y_gantry.STL" />
            </geometry>
        </collision>
    </link>
    <joint name="Y_gantry" type="prismatic">
        <origin xyz="0.38439 0 0.19344" rpy="0 0 0" />
        <parent link="X_gantry_link" />
        <child link="Y_gantry_link" />
        <axis xyz="0.38068 0 0.92471" />
        <limit lower="0" upper="0.16" effort="0" velocity="0" />
    </joint>
    <link name="Z_gantry_link">
        <inertial>
            <origin xyz="-0.456176964938818 0.104673786807244 0.796550541009001" rpy="0 0 0" />
            <mass value="0.403068685283753" />
            <inertia ixx="0.00106965141676946" ixy="-2.56264719037376E-07" ixz="-0.000122132318438366" iyy="0.000362088816461054" iyz="6.50918959412524E-08" izz="0.000823258357320967" />
        </inertial>
        <visual>
            <origin xyz="0 0 0" rpy="0 0 0" />
            <geometry>
                <mesh filename="package://gantry/meshes/Z_gantry.STL" />
            </geometry>
            <material name="">
                <color rgba="0.792156862745098 0.819607843137255 0.933333333333333 1" />
            </material>
        </visual>
        <collision>
            <origin xyz="0 0 0" rpy="0 0 0" />
            <geometry>
                <mesh filename="package://gantry/meshes/Z_gantry.STL" />
            </geometry>
        </collision>
    </link>
    <joint name="Z_gantry" type="prismatic">
        <origin xyz="-0.16631 0.1855 -0.40398" rpy="0 0 0" />
        <parent link="Y_gantry_link" />
        <child link="Z_gantry_link" />
        <axis xyz="0 1 0" />
        <limit lower="-0.03" upper="0.1" effort="0" velocity="0" />
    </joint>
    <link name="R_arm_link">
        <inertial>
            <origin xyz="0.000172992865614646 -9.99205360449618E-05 -0.158657609193451" rpy="0 0 0" />
            <mass value="0.408324104757072" />
            <inertia ixx="0.00270494526203626" ixy="1.76654813115539E-18" ixz="-5.79230427057177E-09" iyy="0.00273630527789283" iyz="4.93932358664184E-09" izz="0.000324233567972814" />
        </inertial>
        <visual>
            <origin xyz="0 0 0" rpy="0 0 0" />
            <geometry>
                <mesh filename="package://gantry/meshes/R_arm.STL" />
            </geometry>
            <material name="">
                <color rgba="0.792156862745098 0.819607843137255 0.933333333333333 1" />
            </material>
        </visual>
        <collision>
            <origin xyz="0 0 0" rpy="0 0 0" />
            <geometry>
                <mesh filename="package://gantry/meshes/R_arm.STL" />
            </geometry>
        </collision>
    </link>
    <joint name="R_arm" type="continuous">
        <origin xyz="-0.47182 0.10003 0.80314" rpy="3.1416 -1.1803 0" />
        <parent link="Z_gantry_link" />
        <child link="R_arm_link" />
        <axis xyz="0 0 1" />
    </joint>
    <link name="TMS_1_link">
        <inertial>
            <origin xyz="-1.73909482529822E-05 3.88578058618805E-15 -4.22443393599536E-05" rpy="0 0 0" />
            <mass value="0.0116350451938087" />
            <inertia ixx="4.37666591544049E-06" ixy="9.70035806134583E-08" ixz="-1.54880682052679E-06" iyy="4.79724370288521E-06" iyz="-3.99339716317391E-08" izz="1.25206583486366E-06" />
        </inertial>
        <visual>
            <origin xyz="0 0 0" rpy="0 0 0" />
            <geometry>
                <mesh filename="package://gantry/meshes/TMS_1.STL" />
            </geometry>
            <material name="">
                <color rgba="0.792156862745098 0.819607843137255 0.933333333333333 1" />
            </material>
        </visual>
        <collision>
            <origin xyz="0 0 0" rpy="0 0 0" />
            <geometry>
                <mesh filename="package://gantry/meshes/TMS_1.STL" />
            </geometry>
        </collision>
    </link>
    <joint name="TMS_1" type="continuous">
        <origin xyz="0.00034733 -0.00025 -0.34785" rpy="2.266 -0.99955 0.78967" />
        <parent link="R_arm_link" />
        <child link="TMS_1_link" />
        <axis xyz="0.38068 0 0.92471" />
    </joint>
    <link name="TMS_HEAD_link">
        <inertial>
            <origin xyz="-0.0274259091798583 -0.011992160041742 0.011290539162308" rpy="0 0 0" />
            <mass value="0.0428411645602252" />
            <inertia ixx="9.69581928427433E-06" ixy="-8.55825624289951E-07" ixz="8.05759898039751E-07" iyy="1.12788800479917E-05" iyz="3.52375864231027E-07" izz="1.13213908836374E-05" />
        </inertial>
        <visual>
            <origin xyz="0 0 0" rpy="0 0 0" />
            <geometry>
                <mesh filename="package://gantry/meshes/TMS_HEAD.STL" />
            </geometry>
            <material name="">
                <color rgba="0.792156862745098 0.819607843137255 0.933333333333333 1" />
            </material>
        </visual>
        <collision>
            <origin xyz="0 0 0" rpy="0 0 0" />
            <geometry>
                <mesh filename="package://gantry/meshes/TMS_HEAD.STL" />
            </geometry>
        </collision>
    </link>
    <joint name="TMS_HEAD" type="continuous">
        <origin xyz="0 0 0" rpy="1.3245 0.71549 -0.069725" />
        <parent link="TMS_1_link" />
        <child link="TMS_HEAD_link" />
        <axis xyz="0.85728 0.37485 -0.35292" />
    </joint>
    <transmission name="X_gantry_trans">
        <type>transmission_interface/SimpleTransmission</type>
        <joint name="X_gantry">
            <hardwareInterface>hardware_interface/PositionJointInterface</hardwareInterface>
        </joint>
        <actuator name="X_gantry_motor">
            <hardwareInterface>hardware_interface/PositionJointInterface</hardwareInterface>
            <mechanicalReduction>1</mechanicalReduction>
        </actuator>
    </transmission>
    <transmission name="Y_gantry_trans">
        <type>transmission_interface/SimpleTransmission</type>
        <joint name="Y_gantry">
            <hardwareInterface>hardware_interface/PositionJointInterface</hardwareInterface>
        </joint>
        <actuator name="Y_gantry_motor">
            <hardwareInterface>hardware_interface/PositionJointInterface</hardwareInterface>
            <mechanicalReduction>1</mechanicalReduction>
        </actuator>
    </transmission>
    <transmission name="Z_gantry_trans">
        <type>transmission_interface/SimpleTransmission</type>
        <joint name="Z_gantry">
            <hardwareInterface>hardware_interface/PositionJointInterface</hardwareInterface>
        </joint>
        <actuator name="Z_gantry_motor">
            <hardwareInterface>hardware_interface/PositionJointInterface</hardwareInterface>
            <mechanicalReduction>1</mechanicalReduction>
        </actuator>
    </transmission>
    <transmission name="R_arm_trans">
        <type>transmission_interface/SimpleTransmission</type>
        <joint name="R_arm">
            <hardwareInterface>hardware_interface/PositionJointInterface</hardwareInterface>
        </joint>
        <actuator name="R_arm_motor">
            <hardwareInterface>hardware_interface/PositionJointInterface</hardwareInterface>
            <mechanicalReduction>1</mechanicalReduction>
        </actuator>
    </transmission>
    <transmission name="TMS_1_trans">
        <type>transmission_interface/SimpleTransmission</type>
        <joint name="TMS_1">
            <hardwareInterface>hardware_interface/PositionJointInterface</hardwareInterface>
        </joint>
        <actuator name="TMS_1_motor">
            <hardwareInterface>hardware_interface/PositionJointInterface</hardwareInterface>
            <mechanicalReduction>1</mechanicalReduction>
        </actuator>
    </transmission>
    <transmission name="TMS_HEAD_trans">
        <type>transmission_interface/SimpleTransmission</type>
        <joint name="TMS_HEAD">
            <hardwareInterface>hardware_interface/PositionJointInterface</hardwareInterface>
        </joint>
        <actuator name="TMS_HEAD_motor">
            <hardwareInterface>hardware_interface/PositionJointInterface</hardwareInterface>
            <mechanicalReduction>1</mechanicalReduction>
        </actuator>
    </transmission>
    <gazebo>
        <plugin name="gazebo_ros_control">
            <robotNamespace>/</robotNamespace>
        </plugin>
    </gazebo>
</robot>

