<?xml version="1.0" encoding="utf-8" ?>
<!-- This URDF was automatically created by SolidWorks to URDF Exporter! Originally created by Stephen Brawner (brawner@gmail.com) 
     Commit Version: 1.6.0-4-g7f85cfe  Build Version: 1.6.7995.38578
     For more information, please see http://wiki.ros.org/sw_urdf_exporter -->
<robot name="gantry">
    <link name="base_link">
        <inertial>
            <origin xyz="0.27339774606297 0.0196335701822426 -0.264075024281507" rpy="0 0 0" />
            <mass value="0.999102566760147" />
            <inertia ixx="0.000487064031842795" ixy="6.79087549106681E-07" ixz="1.23528453698552E-06" iyy="0.0114768570045405" iyz="-2.04757964896779E-08" izz="0.0112945243793064" />
        </inertial>
        <visual>
            <origin xyz="0 0 0" rpy="0 0 0" />
            <geometry>
                <mesh filename="package://gantry/meshes/base_link.STL" />
            </geometry>
            <material name="">
                <color rgba="0.792156862745098 0.819607843137255 0.933333333333333 1" />
            </material>
        </visual>
        <collision>
            <origin xyz="0 0 0" rpy="0 0 0" />
            <geometry>
                <mesh filename="package://gantry/meshes/base_link.STL" />
            </geometry>
        </collision>
    </link>
    <link name="X_Gantry_Link">
        <inertial>
            <origin xyz="-0.250897370416497 0.121219391821721 -0.118974126778769" rpy="0 0 0" />
            <mass value="2.7184408688585" />
            <inertia ixx="0.00586953459875889" ixy="-2.79508273037237E-10" ixz="-7.22728452005846E-09" iyy="0.0300491640122006" iyz="8.45462220164003E-05" izz="0.0312917393952744" />
        </inertial>
        <visual>
            <origin xyz="0 0 0" rpy="0 0 0" />
            <geometry>
                <mesh filename="package://gantry/meshes/X_Gantry_Link.STL" />
            </geometry>
            <material name="">
                <color rgba="0.792156862745098 0.819607843137255 0.933333333333333 1" />
            </material>
        </visual>
        <collision>
            <origin xyz="0 0 0" rpy="0 0 0" />
            <geometry>
                <mesh filename="package://gantry/meshes/X_Gantry_Link.STL" />
            </geometry>
        </collision>
    </link>
    <joint name="x_Gantry" type="prismatic">
        <origin xyz="0.0674975000000973 0.0424999999999915 0.0224999999999924" rpy="1.5707963267949 0 -1.5707963267949" />
        <parent link="base_link" />
        <child link="X_Gantry_Link" />
        <axis xyz="0 0 1" />
        <limit lower="-0.3" upper="0" effort="0" velocity="0" />
    </joint>
    <link name="Y_Gantry_Link">
        <inertial>
            <origin xyz="-0.100144651239331 -0.259006925809135 -0.0449081543375902" rpy="0 0 0" />
            <mass value="1.32530018007878" />
            <inertia ixx="0.00487081879798324" ixy="6.39112939864611E-08" ixz="-1.68886769690012E-07" iyy="0.00261475168874749" iyz="6.95247980957958E-07" izz="0.00721218050776162" />
        </inertial>
        <visual>
            <origin xyz="0 0 0" rpy="0 0 0" />
            <geometry>
                <mesh filename="package://gantry/meshes/Y_Gantry_Link.STL" />
            </geometry>
            <material name="">
                <color rgba="0.792156862745098 0.819607843137255 0.933333333333333 1" />
            </material>
        </visual>
        <collision>
            <origin xyz="0 0 0" rpy="0 0 0" />
            <geometry>
                <mesh filename="package://gantry/meshes/Y_Gantry_Link.STL" />
            </geometry>
        </collision>
    </link>
    <joint name="Y_Gantry" type="prismatic">
        <origin xyz="-0.241997500000031 0.461999999999982 -0.165502499998546" rpy="0 0 0" />
        <parent link="X_Gantry_Link" />
        <child link="Y_Gantry_Link" />
        <axis xyz="1 0 0" />
        <limit lower="0" upper="0.169" effort="0" velocity="0" />
    </joint>
    <link name="Z_Gantry_Link">
        <inertial>
            <origin xyz="-0.0536424640855505 -0.104673786375704 -0.0399261236240839" rpy="0 0 0" />
            <mass value="0.403068685283752" />
            <inertia ixx="0.000772979562738817" ixy="3.73636664016052E-08" ixz="1.36135519292121E-10" iyy="0.000362088816461052" iyz="2.61748959077511E-07" izz="0.00111993021135161" />
        </inertial>
        <visual>
            <origin xyz="0 0 0" rpy="0 0 0" />
            <geometry>
                <mesh filename="package://gantry/meshes/Z_Gantry_Link.STL" />
            </geometry>
            <material name="">
                <color rgba="0.792156862745098 0.819607843137255 0.933333333333333 1" />
            </material>
        </visual>
        <collision>
            <origin xyz="0 0 0" rpy="0 0 0" />
            <geometry>
                <mesh filename="package://gantry/meshes/Z_Gantry_Link.STL" />
            </geometry>
        </collision>
    </link>
    <joint name="Z_Gantry" type="prismatic">
        <origin xyz="-0.0465025000000195 -0.0794677300954897 -0.0589999999999941" rpy="0 0 0" />
        <parent link="Y_Gantry_Link" />
        <child link="Z_Gantry_Link" />
        <axis xyz="0 1 0" />
        <limit lower="-0.137" upper="0" effort="0" velocity="0" />
    </joint>
    <link name="R_Arm_Link">
        <inertial>
            <origin xyz="0.000109473507279578 0.0560505796733769 0.13805236300869" rpy="0 0 0" />
            <mass value="0.64532660044539" />
            <inertia ixx="0.00306981338547555" ixy="1.71181564044435E-09" ixz="6.17685909908221E-09" iyy="0.00302834442807902" iyz="-9.03830003373785E-05" izz="0.000840530479292639" />
        </inertial>
        <visual>
            <origin xyz="0 0 0" rpy="0 0 0" />
            <geometry>
                <mesh filename="package://gantry/meshes/R_Arm_Link.STL" />
            </geometry>
            <material name="">
                <color rgba="0.792156862745098 0.819607843137255 0.933333333333333 1" />
            </material>
        </visual>
        <collision>
            <origin xyz="0 0 0" rpy="0 0 0" />
            <geometry>
                <mesh filename="package://gantry/meshes/R_Arm_Link.STL" />
            </geometry>
        </collision>
    </link>
    <joint name="R_Arm" type="continuous">
        <origin xyz="-0.0534999999999979 -0.100032269904372 -0.0569000000000014" rpy="3.14159265358979 0 3.14159265358979" />
        <parent link="Z_Gantry_Link" />
        <child link="R_Arm_Link" />
        <axis xyz="0 0 1" />
    </joint>
    <link name="TMS_1_Link">
        <inertial>
            <origin xyz="-4.56840156878302E-05 7.36077865326479E-14 -3.34343663865866E-13" rpy="0 0 0" />
            <mass value="0.0116350451938088" />
            <inertia ixx="6.14460426457637E-07" ixy="-1.18091912603685E-20" ixz="3.26582785426984E-20" iyy="4.75482817954653E-06" iyz="-1.39100706744228E-21" izz="5.05668684718519E-06" />
        </inertial>
        <visual>
            <origin xyz="0 0 0" rpy="0 0 0" />
            <geometry>
                <mesh filename="package://gantry/meshes/TMS_1_Link.STL" />
            </geometry>
            <material name="">
                <color rgba="0.792156862745098 0.819607843137255 0.933333333333333 1" />
            </material>
        </visual>
        <collision>
            <origin xyz="0 0 0" rpy="0 0 0" />
            <geometry>
                <mesh filename="package://gantry/meshes/TMS_1_Link.STL" />
            </geometry>
        </collision>
    </link>
    <joint name="TMS_1" type="continuous">
        <origin xyz="0.000346999570831286 0.0752500000000218 0.370600000000016" rpy="1.57079632679489 0 0" />
        <parent link="R_Arm_Link" />
        <child link="TMS_1_Link" />
        <axis xyz="1 0 0" />
    </joint>
    <link name="TMS_HEAD_Link">
        <inertial>
            <origin xyz="-6.06164768379713E-09 3.13335531965109E-08 0.0319916748170583" rpy="0 0 0" />
            <mass value="0.0428412061326084" />
            <inertia ixx="1.16531775928894E-05" ixy="1.27769948468722E-13" ixz="-4.42323913483762E-13" iyy="1.16530809035127E-05" iyz="1.54673107609465E-11" izz="8.98989779656289E-06" />
        </inertial>
        <visual>
            <origin xyz="0 0 0" rpy="0 0 0" />
            <geometry>
                <mesh filename="package://gantry/meshes/TMS_HEAD_Link.STL" />
            </geometry>
            <material name="">
                <color rgba="0.792156862745098 0.819607843137255 0.933333333333333 1" />
            </material>
        </visual>
        <collision>
            <origin xyz="0 0 0" rpy="0 0 0" />
            <geometry>
                <mesh filename="package://gantry/meshes/TMS_HEAD_Link.STL" />
            </geometry>
        </collision>
    </link>
    <joint name="TMS_HEAD" type="continuous">
        <origin xyz="0 0 0" rpy="0 0 3.14159265358979" />
        <parent link="TMS_1_Link" />
        <child link="TMS_HEAD_Link" />
        <axis xyz="0 0 1" />
    </joint>
    <transmission name="trans_x_Gantry">
        <type>transmission_interface/SimpleTransmission</type>
        <joint name="x_Gantry">
            <hardwareInterface>hardware_interface/EffortJointInterface</hardwareInterface>
        </joint>
        <actuator name="x_Gantry_motor">
            <hardwareInterface>hardware_interface/EffortJointInterface</hardwareInterface>
            <mechanicalReduction>1</mechanicalReduction>
        </actuator>
    </transmission>
    <transmission name="trans_Y_Gantry">
        <type>transmission_interface/SimpleTransmission</type>
        <joint name="Y_Gantry">
            <hardwareInterface>hardware_interface/EffortJointInterface</hardwareInterface>
        </joint>
        <actuator name="Y_Gantry_motor">
            <hardwareInterface>hardware_interface/EffortJointInterface</hardwareInterface>
            <mechanicalReduction>1</mechanicalReduction>
        </actuator>
    </transmission>
    <transmission name="trans_Z_Gantry">
        <type>transmission_interface/SimpleTransmission</type>
        <joint name="Z_Gantry">
            <hardwareInterface>hardware_interface/EffortJointInterface</hardwareInterface>
        </joint>
        <actuator name="Z_Gantry_motor">
            <hardwareInterface>hardware_interface/EffortJointInterface</hardwareInterface>
            <mechanicalReduction>1</mechanicalReduction>
        </actuator>
    </transmission>
    <transmission name="trans_R_Arm">
        <type>transmission_interface/SimpleTransmission</type>
        <joint name="R_Arm">
            <hardwareInterface>hardware_interface/EffortJointInterface</hardwareInterface>
        </joint>
        <actuator name="R_Arm_motor">
            <hardwareInterface>hardware_interface/EffortJointInterface</hardwareInterface>
            <mechanicalReduction>1</mechanicalReduction>
        </actuator>
    </transmission>
    <transmission name="trans_TMS_1">
        <type>transmission_interface/SimpleTransmission</type>
        <joint name="TMS_1">
            <hardwareInterface>hardware_interface/EffortJointInterface</hardwareInterface>
        </joint>
        <actuator name="TMS_1_motor">
            <hardwareInterface>hardware_interface/EffortJointInterface</hardwareInterface>
            <mechanicalReduction>1</mechanicalReduction>
        </actuator>
    </transmission>
    <transmission name="trans_TMS_HEAD">
        <type>transmission_interface/SimpleTransmission</type>
        <joint name="TMS_HEAD">
            <hardwareInterface>hardware_interface/EffortJointInterface</hardwareInterface>
        </joint>
        <actuator name="TMS_HEAD_motor">
            <hardwareInterface>hardware_interface/EffortJointInterface</hardwareInterface>
            <mechanicalReduction>1</mechanicalReduction>
        </actuator>
    </transmission>
    <gazebo>
        <plugin name="gazebo_ros_control">
            <robotNamespace>/</robotNamespace>
        </plugin>
    </gazebo>
</robot>

